Workbook

Sheet PROD
A1: e
G3: prod | H3: daily total
B4: Metrics | C4: 162 | D4: Metrics
B5: Infrastructure Integrations | C5: 177 | D5: Metrics | G5: Tracing | H5: 328.63
B6: APM events | C6: 71 | D6: Traces | G6: Infra integrations | H6: 177.7
B7: Logging | C7: 138 | D7: Logs | G7: Metrics | H7: 162.47
B8: Tracing | C8: 328 | D8: Traces | G8: Infrastructure processes | H8: 146.07
B9: Infrastructure Hosts | C9: 18 | D9: Metrics | G9: Logging | H9: 138.41
B10: Infrastrucure Processes | C10: 146 | D10: Metrics | G10: APM Events | H10: 71.21
B11: Custom events | C11: 3 | D11: Logs | G11: Pixie | H11: 47.15
B12: Serverless | C12: 0 | D12: Logs | G12: Infrastructure Hosts | H12: 18.33
B13: Browser events | C13: 4.62 | D13: RUM | G13: Custom Events | H13: 2.97
G14: Browser Events | H14: 4.62
B16: Logs | C16: =C7+C11+C12 -> 141
B17: Metrics | C17: =C4+C5+C9+C10 -> 503 | D17: =C17*1000 -> 503000 | E17: <- numseries
B18: Traces | C18: =C6+C8 -> 399
B19: RUM | C19: =C13 -> 4.62

Sheet Lower
A1: e
G3: Lower
B4: Metrics | C4: 366.23 | D4: Metrics
B5: Infrastructure Integrations | C5: 67.08 | D5: Metrics
B6: APM events | C6: 6.43 | D6: Traces | G6: Logging | H6: 563.52
B7: Logging | C7: 563.52 | D7: Logs | G7: Tracing | H7: 54.53
B8: Tracing | C8: 54.53 | D8: Traces | G8: Infrastructure Processes | H8: 32.18
B9: Infrastructure Hosts | C9: 4.92 | D9: Metrics | G9: Infrastructure Integrations | H9: 67.08
B10: Infrastrucure Processes | C10: 32.18 | D10: Metrics | G10: Metrics | H10: 366.23
B11: Custom events | C11: 1 | D11: Logs | G11: Browser Events | H11: 0.13
B12: Serverless | C12: 0 | D12: Logs | G12: APM Events | H12: 6.43
B13: Browser events | C13: 0.13 | D13: RUM | G13: Infrastructure Hosts | H13: 4.92
G14: Custom Events | H14: 0.96
B16: Logs | C16: =C7+C11+C12 -> 564.52
B17: Metrics | C17: =C4+C5+C9+C10 -> 470.41 | D17: =C17*1000 -> 470410 | E17: <- numseries
B18: Traces | C18: =C6+C8 -> 60.96
B19: RUM | C19: =C13 -> 0.13

Sheet Ingestion 
A1: Prod 1 | E1: prod | F1: daily total
A2: Source | B2: Last 30 days (GB) | C2: Avg Dailly Ingest (GB)
A3: Tracing | B3: 9600.59 | C3: 320.02 | E3: Tracing | F3: =sum(C3,C19) -> 328.63
A4: Infra integrations | B4: 5175.96 | C4: 172.53 | E4: Infra integrations | F4: =sum(C4,C21) -> 177.7
A5: Metrics | B5: 4732.9 | C5: 157.76 | E5: Metrics | F5: =sum(C5,C22) -> 162.47
A6: Infrastructure processes | B6: 4195.72 | C6: 139.86 | E6: Infrastructure processes | F6: =sum(C6,C20) -> 146.07
A7: Logging | B7: 3718.75 | C7: 123.96 | E7: Logging | F7: =sum(C7,C18) -> 138.41
A8: APM Events | B8: 2066.45 | C8: 68.88 | E8: APM Events | F8: =sum(C8,C24) -> 71.21
A9: Pixie | B9: 1414.59 | C9: 47.15 | E9: Pixie | F9: =sum(C9,) -> 47.15
A10: Infrastructure Hosts | B10: 488.94 | C10: 16.3 | E10: Infrastructure Hosts | F10: =sum(C10,C25) -> 18.33
A11: Custom Events | B11: 72.54 | C11: 2.42 | E11: Custom Events | F11: =sum(C11,C26) -> 2.97
A12: Browser Events | B12: 38.75 | C12: 1.29 | E12: Browser Events | F12: =sum(C12,C23) -> 4.62
A13: SLMBytes | B13: 0.17 | C13: 0.01
A15: Prod 2 | E15: Lower
A17: Source | B17: Last 30 days (GB) | C17: Avg Dailly Ingest (GB)
A18: Logging | B18: 433.64 | C18: 14.45 | E18: Logging | F18: =SUM(C31,C44,C59) -> 563.52
A19: Tracing | B19: 258.29 | C19: 8.61 | E19: Tracing | F19: =sum(C34,C47,C58) -> 54.53
A20: Infrastructure Processes | B20: 186.28 | C20: 6.21 | E20: Infrastructure Processes | F20: =sum(C35) -> 32.18
A21: Infrastructure Integrations | B21: 155.05 | C21: 5.17 | E21: Infrastructure Integrations | F21: =sum(C33,C48,C57) -> 67.08
A22: Metrics | B22: 141.32 | C22: 4.71 | E22: Metrics | F22: =sum(C46,C55,C32) -> 366.23
A23: Browser Events | B23: 99.85 | C23: 3.33 | E23: Browser Events | F23: =sum(C40,C61) -> 0.13
A24: APM Events | B24: 69.87 | C24: 2.33 | E24: APM Events | F24: =sum(C37,C49,C60) -> 6.43
A25: Infrastructure Hosts | B25: 61.02 | C25: 2.03 | E25: Infrastructure Hosts | F25: =sum(C38,C50,C56) -> 4.92
A26: Custom Events | B26: 16.54 | C26: 0.55 | E26: Custom Events | F26: =sum(C39,) -> 0.96
A28: Lower 1
A30: Source | B30: Last 30 days (GB) | C30: Avg Dailly Ingest (GB)
A31: Logging | B31: 16902.78 | C31: 563.43
A32: Metrics | B32: 6639.47 | C32: 221.32
A33: Infrastructure Integrations | B33: 1537.3 | C33: 51.24
A34: Tracing | B34: 1081.84 | C34: 36.06
A35: Infrastructure Processes | B35: 965.51 | C35: 32.18
A36: Pixie | B36: 236.8 | C36: 7.89
A37: APM Events | B37: 128.26 | C37: 4.28
A38: Infrastructure Hosts | B38: 93.09 | C38: 3.1
A39: Custom Events | B39: 28.87 | C39: 0.96
A40: Browser Events | B40: 3.07 | C40: 0.1
A42: Lower 2
A44: Source | B44: Last 30 days (GB) | C44: Avg Dailly Ingest (GB)
A45: Logging | B45: 7727.45 | C45: 257.58
A46: Metrics | B46: 4250.59 | C46: 141.69
...

Sheet Sheet2
A1: Usage Metric | B1: Avg. Gb Ingest | C1: % Percentage
A2: LoggingBytes | B2: 43921.034 | C2: =B2/SUM('Area-chart-query'!$B$2:$B$15) -> #REF!
A3: TracingBytes | B3: 18014.072 | C3: =B3/SUM('Area-chart-query'!$B$2:$B$15) -> #REF!
A4: MetricsBytes | B4: 8888.1812 | C4: =B4/SUM('Area-chart-query'!$B$2:$B$15) -> #REF!
A5: InfraIntegrationBytes | B5: 7444.7102 | C5: =B5/SUM('Area-chart-query'!$B$2:$B$15) -> #REF!
A6: ApmEventsBytes | B6: 3450.6226 | C6: =B6/SUM('Area-chart-query'!$B$2:$B$15) -> #REF!
A7: CustomEventsBytes | B7: 2262.5874 | C7: =B7/SUM('Area-chart-query'!$B$2:$B$15) -> #REF!
A8: PixieBytes | B8: 1372.6607 | C8: =B8/SUM('Area-chart-query'!$B$2:$B$15) -> #REF!
A9: InfraHostBytes | B9: 1190.0315 | C9: =B9/SUM('Area-chart-query'!$B$2:$B$15) -> #REF!
A10: ServerlessBytes | B10: 362.06887 | C10: =B10/SUM('Area-chart-query'!$B$2:$B$15) -> #REF!
A11: InfraProcessBytes | B11: 61.40577 | C11: =B11/SUM('Area-chart-query'!$B$2:$B$15) -> #REF!
A12: BrowserEventsBytes | B12: 39.048806 | C12: =B12/SUM('Area-chart-query'!$B$2:$B$15) -> #REF!
A13: NetworkMonitoringBytes | B13: 11.475983 | C13: =B13/SUM('Area-chart-query'!$B$2:$B$15) -> #REF!
... A15: WorkloadsBytes | B15: 0.019492541 | C15: =B15/SUM('Area-chart-query'!$B$2:$B$15) -> #REF!
B16: =SUM('Area-chart-query'!$B$2:$B$15) -> #REF! | C16: =SUM('Area-chart-query'!$C$2:$C$15) -> #REF!
D18: 36 full users at 305 per user
D19: .36 GB for the first 45000
D20: .45 per GB after 45001
